Traceback (most recent call last):
  File "crons/echoBot.py", line 27, in main
    raise Exception
Exception
Traceback (most recent call last):
  File "crons/echoBot.py", line 26, in main
    raise Exception
Exception
